# Errors and Exceptions

In Python, errors and exceptions refer to situations where the interpreter encounters issues during the execution of a program. These issues can be broadly categorized into two types: syntax errors and exceptions.

1. **Syntax Errors:**
   - **Definition:** Syntax errors occur when the Python interpreter encounters code that violates the language's grammar rules. They are the most common type of errors a beginner encounters in python.
   - **Example:** Missing colons, mismatched parentheses, or incorrect indentation are common causes of syntax errors.
   - **Handling:** Syntax errors need to be fixed before the program can be successfully executed. The interpreter will provide an error message indicating the location of the syntax error.

   ```python
   # Syntax Error Example
   if x > 5
      print("x is greater than 5")
   File "/home/taofeekajibade/python-exercises/errors_and_exceptions/syntax_error.py", line 1
    if x > 5
   IndentationError: unexpected indent
```
```python
while True print("Hello World!")
```
```python
while True print('Hello world')
  File "/home/taofeekajibade/python-exercises/errors_and_exceptions/syntax_error.py", line 1
    while True print('Hello world')
                   ^
SyntaxError: invalid syntax
```

2. **Exceptions:**
   - **Definition:** Exceptions are errors that occur during the execution of a program but are not necessarily fatal. Python provides a way to handle these exceptions gracefully.
   - **Example:** Trying to divide by zero, accessing an index that doesn't exist in a list, or attempting to open a non-existent file are examples of situations that can lead to exceptions.
   - **Handling:** Exceptions can be handled using the `try`, `except`, `else`, and `finally` blocks and provide alternative paths or error messages when an exception occurs. So, rather than the code failing to run, it execute the alternative paths or prints the specified error messages.

   ```python
   # Exception Handling Example
   try:
       result = 10 / 0  # Division by zero will raise an exception
   except ZeroDivisionError as e:
       print(f"Error: {e}")
   else:
       print(f"Result: {result}")
   finally:
       print("This block always executes.")
   ```
   In this example, the `try` block attempts to perform a division that may result in a `ZeroDivisionError`. The `except` block catches the exception, prints an error message, and then the `finally` block is executed regardless of whether an exception occurred or not.

```python
while True:
    try:
        x = int(input("Enter a value between 1 and 10 "))
        print(f"You have entered {x}")
        break
    except ValueError:
        print("No! That is not a valid value. Try again. ")
```
This code is a simple example of using a `while` loop and a `try-except` block to repeatedly prompt the user for input until a valid integer within a specified range is entered. Let's break down the execution step by step:

1. **`while True:`:** This creates an infinite loop. The code inside the loop will keep executing until a `break` statement is encountered.

2. **`try:`:** The code within the `try` block is executed. In this case:
   - `x = int(input("Enter a value between 1 and 10 "))`: It prompts the user to enter a value, converts the input to an integer (`int`), and assigns it to the variable `x`.
   - `print(f"You have entered {x}")`: It prints the entered value.
   - `break`: If the input and conversion to an integer are successful, the `break` statement is encountered, and the loop is exited.

3. **`except ValueError:`:** If an exception of type `ValueError` occurs during the execution of the code inside the `try` block, the code within the `except` block is executed:
   - `print("That is not a valid value. Try again. ")`: It prints an error message indicating that the entered value is not a valid integer.

4. After the execution of the `try` or `except` block, the loop continues to the next iteration, prompting the user to enter a value again.

The loop keeps running until a valid integer is entered, at which point the `break` statement is executed, and the program exits the loop.

Here's an example of how the execution might look:

```css
Enter a value between 1 and 10 abc
That is not a valid value. Try again.
Enter a value between 1 and 10 8
You have entered 8
```

In this example, the user initially enters a non-integer value (`abc`), triggering the `except` block. The program then prompts the user again until a valid integer (e.g., `8`) is entered, leading to a successful exit from the loop.

In Python, a `try` statement can have multiple `except` clauses to handle different types of exceptions. Each `except` clause specifies a particular exception type that it can handle. The first matching `except` clause will be executed, and at most one handler will be executed per `try` block.

Here's an example:

```python
try:
    # Some code that may raise exceptions
    x = int(input("Enter a number: "))
    result = 10 / x
    print(f"The result is: {result}")

except ValueError:
    # Handles the case when the user enters a non-integer value
    print("Invalid input. Please enter a valid integer.")

except ZeroDivisionError:
    # Handles the case when the user enters 0 as the denominator
    print("Cannot divide by zero. Please enter a non-zero value.")

except Exception as e:
    # Handles any other exceptions not explicitly caught above
    print(f"An error occurred: {e}")

finally:
    # Code in the finally block will be executed regardless of whether an exception occurred or not
    print("Execution complete.")
```

In this example:

- If the user enters a non-integer value, the `ValueError` handler will be executed.
- If the user enters 0 as the denominator, the `ZeroDivisionError` handler will be executed.
- If any other exception occurs, the `Exception` handler will catch it. The `as e` part allows you to access information about the exception.

Indeed, when using multiple `except` clauses in Python, the order and hierarchy of the exception classes matter. An `except` clause with a more specific exception type should come before a more general one. Furthermore, a class in an `except` clause is compatible with an exception if it is the same class or a base class of that exception.

Here's an example to illustrate this:

```python
class CustomError(Exception):
    pass

try:
    # Some code that may raise exceptions
    raise CustomError("This is a custom exception")

except CustomError:
    # Handle the custom exception
    print("Caught a CustomError")

except ValueError:
    # This block will never be reached, as CustomError is a base class of Exception
    print("Caught a ValueError")

except Exception:
    # This block will be reached for CustomError, as well as other exceptions not caught above
    print("Caught a generic Exception")

finally:
    # Code in the finally block will be executed regardless of whether an exception occurred or not
    print("Execution complete.")
```

In this example, the `except CustomError:` block will catch the `CustomError` exception. If you were to swap the positions of the `except CustomError:` and `except Exception:` blocks, the `except Exception:` block would catch the `CustomError` exception instead. This is because `CustomError` is a subclass of `Exception`.

It's important to carefully order the `except` clauses to ensure that more specific exceptions are caught before more general ones. The interpreter will use the first matching `except` block.

It's important to note that the order of the `except` clauses matters. Python will execute the first matching `except` block, so more specific exceptions should come before more general ones. Additionally, using a catch-all `except Exception` clause can be helpful for handling unexpected errors, but it should be used with caution, as it may catch exceptions you didn't anticipate. Therefore, understanding and handling errors and exceptions is crucial for writing robust and reliable Python programs. It allows developers to anticipate and respond to unexpected situations, improving the overall quality of the software.
